[20:59:05|28-10-21] FATAL ERROR: Traceback (most recent call last):
  File "main.py", line 278, in <module>
    file_objects = open('objects/' + files[i][0], 'r', encoding="utf-8") #
FileNotFoundError: [Errno 2] No such file or directory: 'objects/console.py'

[18:47:47|08-11-21] FATAL ERROR: Traceback (most recent call last):
  File "main.py", line 284, in <module>
    exec(code) # запуск всего кода который мы прочитали из файлов
  File "<string>", line 908
    def draw(self):
      ^
IndentationError: expected an indented block

[21:03:33|08-11-21] FATAL ERROR: Traceback (most recent call last):
  File "main.py", line 284, in <module>
    exec(code) # запуск всего кода который мы прочитали из файлов
  File "<string>", line 916
    self.obj_tanks[0].append(image_label('tanks/body/no_team/tank_base.png', settings.width//2, settings.height//2, scale=self.scale_tank, pixel=False, center=True))
    ^
IndentationError: unexpected indent

[21:20:42|11-11-21] FATAL ERROR: Traceback (most recent call last):
  File "main.py", line 284, in <module>
    exec(code) # запуск всего кода который мы прочитали из файлов
  File "<string>", line 857, in <module>
  File "<string>", line 26, in save_obj
FileNotFoundError: [Errno 2] No such file or directory: 'save/user.pkl'

[21:34:49|11-11-21] FATAL ERROR: Traceback (most recent call last):
  File "main.py", line 284, in <module>
    exec(code) # запуск всего кода который мы прочитали из файлов
  File "<string>", line 823
SyntaxError: positional argument follows keyword argument

[21:35:03|11-11-21] FATAL ERROR: Traceback (most recent call last):
  File "main.py", line 284, in <module>
    exec(code) # запуск всего кода который мы прочитали из файлов
  File "<string>", line 823
SyntaxError: positional argument follows keyword argument

[21:36:07|11-11-21] FATAL ERROR: Traceback (most recent call last):
  File "main.py", line 284, in <module>
    exec(code) # запуск всего кода который мы прочитали из файлов
  File "<string>", line 823
SyntaxError: positional argument follows keyword argument

[21:36:41|11-11-21] FATAL ERROR: Traceback (most recent call last):
  File "main.py", line 284, in <module>
    exec(code) # запуск всего кода который мы прочитали из файлов
  File "<string>", line 823
SyntaxError: positional argument follows keyword argument

[15:35:28|16-11-21] FATAL ERROR: Traceback (most recent call last):
  File "main.py", line 284, in <module>
    exec(code) # запуск всего кода который мы прочитали из файлов
  File "<string>", line 797, in <module>
NameError: name 'os_world' is not defined

[15:36:29|16-11-21] FATAL ERROR: Traceback (most recent call last):
  File "main.py", line 284, in <module>
    exec(code) # запуск всего кода который мы прочитали из файлов
  File "<string>", line 1178, in <module>
  File "<string>", line 667, in __init__
FileNotFoundError: [WinError 3] —истеме не удаетс€ найти указанный путь: 'img/world/other_up'

[15:16:46|24-11-21] FATAL ERROR: Traceback (most recent call last):
  File "C:\Users\100LAR\AppData\Local\Programs\Python\Python37\lib\site-packages\numba\core\typeconv\typeconv.py", line 4, in <module>
    from numba.core.typeconv import _typeconv
ImportError: DLL load failed: Ќе найден указанный модуль.

During handling of the above exception, another exception occurred:

Traceback (most recent call last):
  File "main.py", line 80, in <module>
    import numba # типо оптимизаци€
  File "C:\Users\100LAR\AppData\Local\Programs\Python\Python37\lib\site-packages\numba\__init__.py", line 24, in <module>
    from numba.misc.special import (
  File "C:\Users\100LAR\AppData\Local\Programs\Python\Python37\lib\site-packages\numba\misc\special.py", line 3, in <module>
    from numba.core.typing.typeof import typeof
  File "C:\Users\100LAR\AppData\Local\Programs\Python\Python37\lib\site-packages\numba\core\typing\__init__.py", line 1, in <module>
    from .context import BaseContext, Context
  File "C:\Users\100LAR\AppData\Local\Programs\Python\Python37\lib\site-packages\numba\core\typing\context.py", line 11, in <module>
    from numba.core.typeconv import Conversion, rules
  File "C:\Users\100LAR\AppData\Local\Programs\Python\Python37\lib\site-packages\numba\core\typeconv\rules.py", line 2, in <module>
    from .typeconv import TypeManager, TypeCastingRules
  File "C:\Users\100LAR\AppData\Local\Programs\Python\Python37\lib\site-packages\numba\core\typeconv\typeconv.py", line 17, in <module>
    raise ImportError(msg % (url, reportme, str(e), sys.executable))
ImportError: Numba could not be imported.
If you are seeing this message and are undertaking Numba development work, you may need to re-run:

python setup.py build_ext --inplace

(Also, please check the development set up guide https://numba.pydata.org/numba-doc/latest/developer/contributing.html.)

If you are not working on Numba development:

Please report the error message and traceback, along with a minimal reproducer
at: https://github.com/numba/numba/issues/new

If more help is needed please feel free to speak to the Numba core developers
directly at: https://gitter.im/numba/numba

Thanks in advance for your help in improving Numba!

The original error was: 'DLL load failed: Ќе найден указанный модуль.'
--------------------------------------------------------------------------------
If possible please include the following in your error report:

sys.executable: C:\Users\100LAR\AppData\Local\Programs\Python\Python37\python.exe


[15:26:16|24-11-21] FATAL ERROR: Traceback (most recent call last):
  File "C:\Users\100LAR\AppData\Local\Programs\Python\Python37\lib\site-packages\numba\core\typeconv\typeconv.py", line 4, in <module>
    from numba.core.typeconv import _typeconv
ImportError: DLL load failed: Ќе найден указанный модуль.

During handling of the above exception, another exception occurred:

Traceback (most recent call last):
  File "main.py", line 80, in <module>
    import numba # типо оптимизаци€
  File "C:\Users\100LAR\AppData\Local\Programs\Python\Python37\lib\site-packages\numba\__init__.py", line 24, in <module>
    from numba.misc.special import (
  File "C:\Users\100LAR\AppData\Local\Programs\Python\Python37\lib\site-packages\numba\misc\special.py", line 3, in <module>
    from numba.core.typing.typeof import typeof
  File "C:\Users\100LAR\AppData\Local\Programs\Python\Python37\lib\site-packages\numba\core\typing\__init__.py", line 1, in <module>
    from .context import BaseContext, Context
  File "C:\Users\100LAR\AppData\Local\Programs\Python\Python37\lib\site-packages\numba\core\typing\context.py", line 11, in <module>
    from numba.core.typeconv import Conversion, rules
  File "C:\Users\100LAR\AppData\Local\Programs\Python\Python37\lib\site-packages\numba\core\typeconv\rules.py", line 2, in <module>
    from .typeconv import TypeManager, TypeCastingRules
  File "C:\Users\100LAR\AppData\Local\Programs\Python\Python37\lib\site-packages\numba\core\typeconv\typeconv.py", line 17, in <module>
    raise ImportError(msg % (url, reportme, str(e), sys.executable))
ImportError: Numba could not be imported.
If you are seeing this message and are undertaking Numba development work, you may need to re-run:

python setup.py build_ext --inplace

(Also, please check the development set up guide https://numba.pydata.org/numba-doc/latest/developer/contributing.html.)

If you are not working on Numba development:

Please report the error message and traceback, along with a minimal reproducer
at: https://github.com/numba/numba/issues/new

If more help is needed please feel free to speak to the Numba core developers
directly at: https://gitter.im/numba/numba

Thanks in advance for your help in improving Numba!

The original error was: 'DLL load failed: Ќе найден указанный модуль.'
--------------------------------------------------------------------------------
If possible please include the following in your error report:

sys.executable: C:\Users\100LAR\AppData\Local\Programs\Python\Python37\python.exe


[15:27:34|24-11-21] FATAL ERROR: Traceback (most recent call last):
  File "C:\Users\100LAR\AppData\Local\Programs\Python\Python37\lib\site-packages\numba\core\typeconv\typeconv.py", line 4, in <module>
    from numba.core.typeconv import _typeconv
ImportError: DLL load failed: Ќе найден указанный модуль.

During handling of the above exception, another exception occurred:

Traceback (most recent call last):
  File "main.py", line 80, in <module>
    import numba # типо оптимизаци€
  File "C:\Users\100LAR\AppData\Local\Programs\Python\Python37\lib\site-packages\numba\__init__.py", line 24, in <module>
    from numba.misc.special import (
  File "C:\Users\100LAR\AppData\Local\Programs\Python\Python37\lib\site-packages\numba\misc\special.py", line 3, in <module>
    from numba.core.typing.typeof import typeof
  File "C:\Users\100LAR\AppData\Local\Programs\Python\Python37\lib\site-packages\numba\core\typing\__init__.py", line 1, in <module>
    from .context import BaseContext, Context
  File "C:\Users\100LAR\AppData\Local\Programs\Python\Python37\lib\site-packages\numba\core\typing\context.py", line 11, in <module>
    from numba.core.typeconv import Conversion, rules
  File "C:\Users\100LAR\AppData\Local\Programs\Python\Python37\lib\site-packages\numba\core\typeconv\rules.py", line 2, in <module>
    from .typeconv import TypeManager, TypeCastingRules
  File "C:\Users\100LAR\AppData\Local\Programs\Python\Python37\lib\site-packages\numba\core\typeconv\typeconv.py", line 17, in <module>
    raise ImportError(msg % (url, reportme, str(e), sys.executable))
ImportError: Numba could not be imported.
If you are seeing this message and are undertaking Numba development work, you may need to re-run:

python setup.py build_ext --inplace

(Also, please check the development set up guide https://numba.pydata.org/numba-doc/latest/developer/contributing.html.)

If you are not working on Numba development:

Please report the error message and traceback, along with a minimal reproducer
at: https://github.com/numba/numba/issues/new

If more help is needed please feel free to speak to the Numba core developers
directly at: https://gitter.im/numba/numba

Thanks in advance for your help in improving Numba!

The original error was: 'DLL load failed: Ќе найден указанный модуль.'
--------------------------------------------------------------------------------
If possible please include the following in your error report:

sys.executable: C:\Users\100LAR\AppData\Local\Programs\Python\Python37\python.exe


[15:28:51|24-11-21] FATAL ERROR: Traceback (most recent call last):
  File "main.py", line 80, in <module>
    import numba # типо оптимизаци€
  File "C:\Users\100LAR\AppData\Local\Programs\Python\Python37\lib\site-packages\numba\__init__.py", line 196, in <module>
    import numba.typed
  File "C:\Users\100LAR\AppData\Local\Programs\Python\Python37\lib\site-packages\numba\typed\__init__.py", line 3, in <module>
    from .typeddict import Dict
  File "C:\Users\100LAR\AppData\Local\Programs\Python\Python37\lib\site-packages\numba\typed\typeddict.py", line 19, in <module>
    @njit
  File "C:\Users\100LAR\AppData\Local\Programs\Python\Python37\lib\site-packages\numba\decorators.py", line 238, in njit
    return jit(*args, **kws)
  File "C:\Users\100LAR\AppData\Local\Programs\Python\Python37\lib\site-packages\numba\decorators.py", line 175, in jit
    return wrapper(pyfunc)
  File "C:\Users\100LAR\AppData\Local\Programs\Python\Python37\lib\site-packages\numba\decorators.py", line 191, in wrapper
    **dispatcher_args)
  File "C:\Users\100LAR\AppData\Local\Programs\Python\Python37\lib\site-packages\numba\dispatcher.py", line 650, in __init__
    self.targetctx = self.targetdescr.target_context
  File "C:\Users\100LAR\AppData\Local\Programs\Python\Python37\lib\site-packages\numba\targets\registry.py", line 50, in target_context
    return self._toplevel_target_context
  File "C:\Users\100LAR\AppData\Local\Programs\Python\Python37\lib\site-packages\numba\utils.py", line 390, in __get__
    res = instance.__dict__[self.name] = self.func(instance)
  File "C:\Users\100LAR\AppData\Local\Programs\Python\Python37\lib\site-packages\numba\targets\registry.py", line 34, in _toplevel_target_context
    return cpu.CPUContext(self.typing_context)
  File "C:\Users\100LAR\AppData\Local\Programs\Python\Python37\lib\site-packages\numba\targets\base.py", line 260, in __init__
    self.init()
  File "C:\Users\100LAR\AppData\Local\Programs\Python\Python37\lib\site-packages\numba\compiler_lock.py", line 32, in _acquire_compile_lock
    return func(*args, **kwargs)
  File "C:\Users\100LAR\AppData\Local\Programs\Python\Python37\lib\site-packages\numba\targets\cpu.py", line 51, in init
    self._internal_codegen = codegen.JITCPUCodegen("numba.exec")
  File "C:\Users\100LAR\AppData\Local\Programs\Python\Python37\lib\site-packages\numba\targets\codegen.py", line 628, in __init__
    self._init(self._llvm_module)
  File "C:\Users\100LAR\AppData\Local\Programs\Python\Python37\lib\site-packages\numba\targets\codegen.py", line 637, in _init
    tm = target.create_target_machine(**tm_options)
TypeError: create_target_machine() got an unexpected keyword argument 'jitdebug'

[15:30:18|24-11-21] FATAL ERROR: Traceback (most recent call last):
  File "main.py", line 88, in <module>
    from PodSixNet.Server import Server
ModuleNotFoundError: No module named 'PodSixNet'

[15:40:32|24-11-21] FATAL ERROR: Traceback (most recent call last):
  File "C:\Users\100LAR\AppData\Local\Programs\Python\Python37\lib\configparser.py", line 788, in get
    value = d[option]
  File "C:\Users\100LAR\AppData\Local\Programs\Python\Python37\lib\collections\__init__.py", line 916, in __getitem__
    return self.__missing__(key)            # support subclasses that define __missing__
  File "C:\Users\100LAR\AppData\Local\Programs\Python\Python37\lib\collections\__init__.py", line 908, in __missing__
    raise KeyError(key)
KeyError: 'use_numba'

During handling of the above exception, another exception occurred:

Traceback (most recent call last):
  File "main.py", line 240, in <module>
    settings = settings() # инициализаци€ класса с настройками
  File "main.py", line 196, in __init__
    self.read_settings() # читаем настроки
  File "main.py", line 236, in read_settings
    self.use_numba = True if (config.get("User_interface", "use_numba")).lower() == 'true' else False
  File "C:\Users\100LAR\AppData\Local\Programs\Python\Python37\lib\configparser.py", line 791, in get
    raise NoOptionError(option, section)
configparser.NoOptionError: No option 'use_numba' in section: 'User_interface'

[15:40:48|24-11-21] FATAL ERROR: Traceback (most recent call last):
  File "main.py", line 240, in <module>
    settings = settings() # инициализаци€ класса с настройками
  File "main.py", line 196, in __init__
    self.read_settings() # читаем настроки
  File "main.py", line 238, in read_settings
    import numba # типо оптимизаци€
  File "C:\Users\100LAR\AppData\Local\Programs\Python\Python37\lib\site-packages\numba\__init__.py", line 196, in <module>
    import numba.typed
  File "C:\Users\100LAR\AppData\Local\Programs\Python\Python37\lib\site-packages\numba\typed\__init__.py", line 3, in <module>
    from .typeddict import Dict
  File "C:\Users\100LAR\AppData\Local\Programs\Python\Python37\lib\site-packages\numba\typed\typeddict.py", line 19, in <module>
    @njit
  File "C:\Users\100LAR\AppData\Local\Programs\Python\Python37\lib\site-packages\numba\decorators.py", line 238, in njit
    return jit(*args, **kws)
  File "C:\Users\100LAR\AppData\Local\Programs\Python\Python37\lib\site-packages\numba\decorators.py", line 175, in jit
    return wrapper(pyfunc)
  File "C:\Users\100LAR\AppData\Local\Programs\Python\Python37\lib\site-packages\numba\decorators.py", line 191, in wrapper
    **dispatcher_args)
  File "C:\Users\100LAR\AppData\Local\Programs\Python\Python37\lib\site-packages\numba\dispatcher.py", line 650, in __init__
    self.targetctx = self.targetdescr.target_context
  File "C:\Users\100LAR\AppData\Local\Programs\Python\Python37\lib\site-packages\numba\targets\registry.py", line 50, in target_context
    return self._toplevel_target_context
  File "C:\Users\100LAR\AppData\Local\Programs\Python\Python37\lib\site-packages\numba\utils.py", line 390, in __get__
    res = instance.__dict__[self.name] = self.func(instance)
  File "C:\Users\100LAR\AppData\Local\Programs\Python\Python37\lib\site-packages\numba\targets\registry.py", line 34, in _toplevel_target_context
    return cpu.CPUContext(self.typing_context)
  File "C:\Users\100LAR\AppData\Local\Programs\Python\Python37\lib\site-packages\numba\targets\base.py", line 260, in __init__
    self.init()
  File "C:\Users\100LAR\AppData\Local\Programs\Python\Python37\lib\site-packages\numba\compiler_lock.py", line 32, in _acquire_compile_lock
    return func(*args, **kwargs)
  File "C:\Users\100LAR\AppData\Local\Programs\Python\Python37\lib\site-packages\numba\targets\cpu.py", line 51, in init
    self._internal_codegen = codegen.JITCPUCodegen("numba.exec")
  File "C:\Users\100LAR\AppData\Local\Programs\Python\Python37\lib\site-packages\numba\targets\codegen.py", line 628, in __init__
    self._init(self._llvm_module)
  File "C:\Users\100LAR\AppData\Local\Programs\Python\Python37\lib\site-packages\numba\targets\codegen.py", line 637, in _init
    tm = target.create_target_machine(**tm_options)
TypeError: create_target_machine() got an unexpected keyword argument 'jitdebug'

